Traceback (most recent call last):
  File "<frozen runpy>", line 198, in _run_module_as_main
  File "<frozen runpy>", line 88, in _run_code
  File "/usr/lib/python3.13/unittest/__main__.py", line 18, in <module>
    main(module=None)
    ~~~~^^^^^^^^^^^^^
  File "/usr/lib/python3.13/unittest/main.py", line 103, in __init__
    self.parseArgs(argv)
    ~~~~~~~~~~~~~~^^^^^^
  File "/usr/lib/python3.13/unittest/main.py", line 142, in parseArgs
    self.createTests()
    ~~~~~~~~~~~~~~~~^^
  File "/usr/lib/python3.13/unittest/main.py", line 153, in createTests
    self.test = self.testLoader.loadTestsFromNames(self.testNames,
                ~~~~~~~~~~~~~~~~~~~~~~~~~~~~~~~~~~^^^^^^^^^^^^^^^^
                                                   self.module)
                                                   ^^^^^^^^^^^^
  File "/usr/lib/python3.13/unittest/loader.py", line 207, in loadTestsFromNames
    suites = [self.loadTestsFromName(name, module) for name in names]
              ~~~~~~~~~~~~~~~~~~~~~~^^^^^^^^^^^^^^
  File "/usr/lib/python3.13/unittest/loader.py", line 137, in loadTestsFromName
    module = __import__(module_name)
  File "/usr/local/google/home/ameenahb/development/accelerated-platforms/modules/python/tests/test_google_genmedia/test_retry.py", line 75, in <module>
    from custom_nodes.google_genmedia.retry import retry_on_api_error
  File "<frozen importlib._bootstrap>", line 1360, in _find_and_load
  File "<frozen importlib._bootstrap>", line 1320, in _find_and_load_unlocked
  File "/usr/lib/python3.13/unittest/mock.py", line 692, in __getattr__
    raise AttributeError(name)
AttributeError: __spec_
