Traceback (most recent call last):
  File "<frozen runpy>", line 198, in _run_module_as_main
  File "<frozen runpy>", line 88, in _run_code
  File "/usr/lib/python3.13/unittest/__main__.py", line 18, in <module>
    main(module=None)
    ~~~~^^^^^^^^^^^^^
  File "/usr/lib/python3.13/unittest/main.py", line 103, in __init__
    self.parseArgs(argv)
    ~~~~~~~~~~~~~~^^^^^^
  File "/usr/lib/python3.13/unittest/main.py", line 142, in parseArgs
    self.createTests()
    ~~~~~~~~~~~~~~~~^^
  File "/usr/lib/python3.13/unittest/main.py", line 153, in createTests
    self.test = self.testLoader.loadTestsFromNames(self.testNames,
                ~~~~~~~~~~~~~~~~~~~~~~~~~~~~~~~~~~^^^^^^^^^^^^^^^^
                                                   self.module)
                                                   ^^^^^^^^^^^^
  File "/usr/lib/python3.13/unittest/loader.py", line 207, in loadTestsFromNames
    suites = [self.loadTestsFromName(name, module) for name in names]
              ~~~~~~~~~~~~~~~~~~~~~~^^^^^^^^^^^^^^
  File "/usr/lib/python3.13/unittest/loader.py", line 137, in loadTestsFromName
    module = __import__(module_name)
  File "/usr/local/google/home/ameenahb/development/accelerated-platforms/modules/python/tests/test_google_genmedia/test_base_api.py", line 72, in <module>
    from custom_nodes.google_genmedia.base_api import GoogleGenAIBaseAPI
  File "/usr/local/google/home/ameenahb/development/accelerated-platforms/modules/python/src/custom_nodes/google_genmedia/__init__.py", line 29, in <module>
    from .helper_nodes import NODE_CLASS_MAPPINGS as HELPER_NODE_CLASS_MAPPINGS
  File "/usr/local/google/home/ameenahb/development/accelerated-platforms/modules/python/src/custom_nodes/google_genmedia/helper_nodes.py", line 24, in <module>
    import cv2
  File "/usr/local/google/home/ameenahb/venv/lib/python3.13/site-packages/cv2/__init__.py", line 12, in <module>
    import numpy.core.multiarray
  File "<frozen importlib._bootstrap>", line 1360, in _find_and_load
  File "<frozen importlib._bootstrap>", line 1320, in _find_and_load_unlocked
  File "/usr/lib/python3.13/unittest/mock.py", line 692, in __getattr__
    raise AttributeError(name)
AttributeError: __spec__
